Workbook

Sheet Key Stats
A5: Apple Inc. (NasdaqGS:AAPL) > Financials > Key Stats
A7: In Millions of the trading currency, except per share items. | B7: Currency: | C7: Trading Currency | E7: Conversion: | F7: Historical
B8: Order: | C8: Latest on Right | E8: Units: | F8: S&P Capital IQ (Default)
B9: Decimals: | C9: Capital IQ (Default) | E9: Dilution: | F9: Basic
A12: Key Financials¹
A13: For the Fiscal Period Ending | B13: 12 months Sep-28-2013A | C13: 12 months Sep-27-2014A | D13: 12 months Sep-26-2015A | E13: 12 months Sep-24-2016A | F13: 12 months Sep-30-2017A | G13: 12 months Sep-29-2018A | H13: 12 months Sep-28-2019A | I13: 12 months Sep-26-2020A | J13: 12 months Sep-25-2021A | K13: 12 months Sep-24-2022A | L13: 12 months Sep-30-2023A | M13: LTM² 12 months Dec-30-2023A | N13: 12 months† Sep-30-2024E | O13: 12 months Sep-30-2025E | P13: 12 months Sep-30-2026E
A14: Currency | B14: USD | C14: USD | D14: USD | E14: USD | F14: USD | G14: USD | H14: USD | I14: USD | J14: USD | K14: USD | L14: USD | M14: USD | N14: USD | O14: USD | P14: USD
A16: Total Revenue | B16: 170910 | C16: 182795 | D16: 233715 | E16: 215639 | F16: 229234 | G16: 265595 | H16: 260174 | I16: 274515 | J16: 365817 | K16: 394328 | L16: 383285 | M16: 385706 | N16: 388204.69 | O16: 412561.7 | P16: 435593.04
A17: Growth Over Prior Year | B17: 0.09202 | C17: 0.069539 | D17: 0.278563 | E17: -0.077343 | F17: 0.063045 | G17: 0.158619 | H17: -0.020411 | I17: 0.05512 | J17: 0.332593 | K17: 0.077937 | L17: -0.028005 | M17: -0.004725 | N17: 0.012835605 | O17: 0.062742677 | P17: 0.055825209
A19: Gross Profit | B19: 64304 | C19: 70537 | D19: 93626 | E19: 84263 | F19: 88186 | G19: 101839 | H19: 98392 | I19: 104956 | J19: 152836 | K19: 170782 | L19: 169148 | M19: 173671 | N19: - | O19: - | P19: -
A20: Margin % | B20: 0.376244 | C20: 0.38588 | D20: 0.400599 | E20: 0.390759 | F20: 0.384698 | G20: 0.383437 | H20: 0.378177 | I20: 0.382332 | J20: 0.417793 | K20: 0.433096 | L20: 0.441311 | M20: 0.450267 | N20: 0.458179 | O20: 0.458491 | P20: 0.4585781
A22: EBITDA | B22: 55756 | C22: 60449 | D22: 82487 | E22: 70529 | F22: 71501 | G22: 81801 | H22: 76477 | I22: 77344 | J22: 120233 | K22: 130541 | L22: 125820 | M22: 130109 | N22: 132236.37 | O22: 141059.85 | P22: 148981.06
A23: Margin % | B23: 0.32623 | C23: 0.330692 | D23: 0.352938 | E23: 0.327069 | F23: 0.311912 | G23: 0.307991 | H23: 0.293945 | I23: 0.281747 | J23: 0.328669 | K23: 0.331046 | L23: 0.328267 | M23: 0.337326 | N23: 0.34063568 | O23: 0.34191214 | P23: 0.34201892
A25: EBIT | B25: 48999 | C25: 52503 | D25: 71230 | E25: 60024 | F25: 61344 | G25: 70898 | H25: 63930 | I25: 66288 | J25: 108949 | K25: 119437 | L25: 114301 | M25: 118658 | N25: 120143.29 | O25: 127664.82 | P25: 135528.9
A26: Margin % | B26: 0.286694 | C26: 0.287223 | D26: 0.304772 | E26: 0.278354 | F26: 0.267604 | G26: 0.26694 | H26: 0.24572 | I26: 0.241473 | J26: 0.297823 | K26: 0.302887 | L26: 0.298214 | M26: 0.307638 | N26: 0.30948437 | O26: 0.3094442 | P26: 0.31113652
A28: Earnings from Cont. Ops. | B28: 37037 | C28: 39510 | D28: 53394 | E28: 45687 | F28: 48351 | G28: 59531 | H28: 55256 | I28: 57411 | J28: 94680 | K28: 99803 | L28: 96995 | M28: 100913 | N28: - | O28: - | P28: -
A29: Margin % | B29: 0.216704 | C29: 0.216143 | D29: 0.228457 | E29: 0.211867 | F29: 0.210924 | G29: 0.224142 | H29: 0.21238 | I29: 0.209136 | J29: 0.258817 | K29: 0.253096 | L29: 0.253062 | M29: 0.261631 | N29: - | O29: - | P29: -
A31: Net Income | B31: 37037 | C31: 39510 | D31: 53394 | E31: 45687 | F31: 48351 | G31: 59531 | H31: 55256 | I31: 57411 | J31: 94680 | K31: 99803 | L31: 96995 | M31: 100913 | N31: 100916.95 | O31: 107037.47 | P31: 114247.86
A32: Margin % | B32: 0.216704 | C32: 0.216143 | D32: 0.228457 | E32: 0.211867 | F32: 0.210924 | G32: 0.224142 | H32: 0.21238 | I32: 0.209136 | J32: 0.258817 | K32: 0.253096 | L32: 0.253062 | M32: 0.261631 | N32: 0.25995808 | O32: 0.25944597 | P32: 0.2622812
A34: Diluted EPS Excl. Extra Items³ | B34: 1.42 | C34: 1.6125 | D34: 2.305 | E34: 2.0775 | F34: 2.3025 | G34: 2.98 | H34: 2.97 | I34: 3.28 | J34: 5.61 | K34: 6.11 | L34: 6.13 | M34: 6.418925 | N34: 6.56319 | O34: 7.16097 | P34: 7.78477
A35: Growth Over Prior Year | B35: -0.099842 | C35: 0.135563 | D35: 0.429457 | E35: -0.098699 | F35: 0.108303 | G35: 0.294245 | H35: -0.003356 | I35: 0.104377 | J35: 0.710365 | K35: 0.089126 | L35: 0.003273 | M35: 0.092921 | N35: 0.07066721 | O35: 0.091080709 | P35: 0.087111104
A38: Currency | B38: USD | C38: USD | D38: USD | E38: USD | F38: USD | G38: USD | H38: USD | I38: USD | J38: USD | K38: USD | L38: USD | M38: USD | N38: USD | O38: USD | P38: USD
A39: Exchange Rate | B39: 1 | C39: 1 | D39: 1 | E39: 1 | F39: 1 | G39: 1 | H39: 1 | I39: 1 | J39: 1 | K39: 1 | L39: 1 | M39: 1 | N39: 1 | O39: 1 | P39: 1
A40: Conversion Method | B40: H | C40: H | D40: H | E40: H | F40: H | G40: H | H40: H | I40: H | J40: H | K40: H | L40: H | M40: H | N40: S | O40: S | P40: S
A42: ¹All results are taken from the most recently filed statement for each period. When there has been more than one, earlier filings can be viewed on the individual statement pages.
A43: ²Growth rates for the LTM period are calculated against the LTM period ending 12 months before.
A44: ³All forward period figures are consensus mean estimates provided by the brokers and may not be on a comparable basis as financials.
A45: †Growth rates for forward periods are calculated against prior period estimates or actual pro forma results as disclosed on the Estimates Consensus page.
A46: Growth Rates are calculated in originally reported currency only and will not reflect any currency conversion selected above.
A48: Current Capitalization (Millions of USD)
A49: Currency | B49: USD
A50: Share Price | B50: 172.62
A51: Shares Out. | B51: 15441.881
A53: Market Capitalization | B53: 2665577.5
A54: - Cash & Short Term Investments | B54: 73100
A55: + Total Debt | B55: 108040
A56: + Pref. Equity | B56: -
A57: + Total Minority Interest | B57: -
A58: - Long Term Marketable Securities | B58: 99475
A59: = Total Enterprise Value (TEV) | B59: 2601042.5
...

Sheet IS
A5: Apple Inc. (NasdaqGS:AAPL) > Financials > Income Statement
A7: In Millions of the reported currency, except per share items. | B7: Template: | C7: Standard | E7: Restatement: | F7: Latest Filings
B8: Period Type: | C8: Annual | E8: Order: | F8: Latest on Right
B9: Currency: | C9: Reported Currency | E9: Conversion: | F9: Historical
B10: Units: | C10: S&P Capital IQ (Default) | E10: Decimals: | F10: Capital IQ (Default)
B11: Source: | C11: Capital IQ & Proprietary Data
A14: Income Statement
A15: For the Fiscal Period Ending | B15: 12 months Sep-28-2013 | C15: 12 months Sep-27-2014 | D15: 12 months Sep-26-2015 | E15: 12 months Sep-24-2016 | F15: 12 months Sep-30-2017 | G15: 12 months Sep-29-2018 | H15: 12 months Sep-28-2019 | I15: 12 months Sep-26-2020 | J15: 12 months Sep-25-2021 | K15: 12 months Sep-24-2022 | L15: 12 months Sep-30-2023 | M15: LTM 12 months Dec-30-2023
A16: Currency | B16: USD | C16: USD | D16: USD | E16: USD | F16: USD | G16: USD | H16: USD | I16: USD | J16: USD | K16: USD | L16: USD | M16: USD
A18: Revenue | B18: 170910 | C18: 182795 | D18: 233715 | E18: 215639 | F18: 229234 | G18: 265595 | H18: 260174 | I18: 274515 | J18: 365817 | K18: 394328 | L18: 383285 | M18: 385706
A19: = Net Sales | B19: 170910 | C19: 182795 | D19: 233715 | E19: 215639 | F19: - | G19: - | H19: - | I19: - | J19: - | K19: - | L19: - | M19: -
A20: + Net Sale service | B20: - | C20: - | D20: - | E20: - | F20: 32700 | G20: 39748 | H20: 46291 | I20: 53768 | J20: 68425 | K20: 78129 | L20: 85200 | M20: -
A21: + Net Sales Product | B21: - | C21: - | D21: - | E21: - | F21: 196534 | G21: 225847 | H21: 213883 | I21: 220747 | J21: 297392 | K21: 316199 | L21: 298085 | M21: -
A22: Other Revenue | B22: - | C22: - | D22: - | E22: - | F22: - | G22: - | H22: - | I22: - | J22: - | K22: - | L22: - | M22: -
A23: Total Revenue | B23: 170910 | C23: 182795 | D23: 233715 | E23: 215639 | F23: 229234 | G23: 265595 | H23: 260174 | I23: 274515 | J23: 365817 | K23: 394328 | L23: 383285 | M23: 385706
A25: Cost Of Goods Sold | B25: 106606 | C25: 112258 | D25: 140089 | E25: 131376 | F25: 141048 | G25: 163756 | H25: 161782 | I25: 169559 | J25: 212981 | K25: 223546 | L25: 214137 | M25: 212035
A26: = Services | B26: - | C26: - | D26: - | E26: - | F26: 14711 | G26: 15592 | H26: 16786 | I26: 18273 | J26: 20715 | K26: 22075 | L26: 24855 | M26: -
A27: + Cost of Sales-product | B27: - | C27: - | D27: - | E27: - | F27: 126337 | G27: 148164 | H27: 144996 | I27: 151286 | J27: 192266 | K27: 201471 | L27: 189282 | M27: -
A28: + Cost of Sales | B28: 106606 | C28: 112258 | D28: 140089 | E28: 131376 | F28: - | G28: - | H28: - | I28: - | J28: - | K28: - | L28: - | M28: -
A29: - SBC (Cost of Revenues) | B29: 350 | C29: 450 | D29: 575 | E29: 769 | F29: - | G29: - | H29: - | I29: - | J29: - | K29: - | L29: - | M29: -
A30: + SBC (Cost of Revenues) | B30: 350 | C30: 450 | D30: 575 | E30: 769 | F30: - | G30: - | H30: - | I30: - | J30: - | K30: - | L30: - | M30: -
A31: Gross Profit | B31: 64304 | C31: 70537 | D31: 93626 | E31: 84263 | F31: 88186 | G31: 101839 | H31: 98392 | I31: 104956 | J31: 152836 | K31: 170782 | L31: 169148 | M31: 173671
O32: 5-yr avg | P32: Our Estimate(Using near term)
A33: Gross Margin (Product) | F33: =(F21-F27)/F21 -> 0.35717484 | G33: =(G21-G27)/G21 -> 0.34396295 | H33: =(H21-H27)/H21 -> 0.32207796 | I33: =(I21-I27)/I21 -> 0.31466339 | J33: =(J21-J27)/J21 -> 0.35349303 | K33: =(K21-K27)/K21 -> 0.3628348 | L33: =(L21-L27)/L21 -> 0.36500663 | O33: =AVERAGE(H33:L33) -> 0.34361516 | P33: 0.36
A34: Gross Margin (Service) | F34: =(F20-F26)/F20 -> 0.55012232 | G34: =(G20-G26)/G20 -> 0.60772869 | H34: =(H20-H26)/H20 -> 0.63738092 | I34: =(I20-I26)/I20 -> 0.66015102 | J34: =(J20-J26)/J20 -> 0.69725977 | K34: =(K20-K26)/K20 -> 0.71745447 | L34: =(L20-L26)/L20 -> 0.70827465 | O34: =AVERAGE(H34:L34) -> 0.68410416 | P34: 0.71
A36: Selling General & Admin Exp. | B36: 10830 | C36: 11993 | D36: 14329 | E36: 14194 | F36: 15261 | G36: 16705 | H36: 18245 | I36: 19916 | J36: 21973 | K36: 25094 | L36: 24932 | M36: 25111
A37: = Advertising Expenses | B37: 1100 | C37: - | D37: - | E37: - | F37: - | G37: - | H37: - | I37: - | J37: - | K37: - | L37: - | M37: -
A38: + Selling, General and Administrative | B38: - | C38: - | D38: - | E38: - | F38: 15261 | G38: 16705 | H38: 18245 | I38: 19916 | J38: 21973 | K38: 25094 | L38: 24932 | M38: -
A39: + Selling, General and Administrative | B39: 10830 | C39: 11993 | D39: 14329 | E39: 14194 | F39: - | G39: - | H39: - | I39: - | J39: - | K39: - | L39: - | M39: -
A40: - SBC (SG&A Exp.) | B40: 986 | C40: 1197 | D40: 1475 | E40: 1552 | F40: - | G40: - | H40: - | I40: - | J40: - | K40: - | L40: - | M40: -
A41: - Advertising Expenses | B41: 1100 | C41: - | D41: - | E41: - | F41: - | G41: - | H41: - | I41: - | J41: - | K41: - | L41: - | M41: -
A42: + SBC (SG&A Exp.) | B42: 986 | C42: 1197 | D42: 1475 | E42: 1552 | F42: - | G42: - | H42: - | I42: - | J42: - | K42: - | L42: - | M42: -
A43: R & D Exp. | B43: 4475 | C43: 6041 | D43: 8067 | E43: 10045 | F43: 11581 | G43: 14236 | H43: 16217 | I43: 18752 | J43: 21914 | K43: 26251 | L43: 29915 | M43: 29902
A44: = Research and Development | B44: - | C44: - | D44: - | E44: - | F44: 11581 | G44: 14236 | H44: 16217 | I44: 18752 | J44: 21914 | K44: 26251 | L44: 29915 | M44: -
A45: + Research and Development | B45: 4475 | C45: 6041 | D45: 8067 | E45: 10045 | F45: - | G45: - | H45: - | I45: - | J45: - | K45: - | L45: - | M45: -
A46: - SBC (R&D Exp.) | B46: 917 | C46: 1216 | D46: 1536 | E46: 1889 | F46: - | G46: - | H46: - | I46: - | J46: - | K46: - | L46: - | M46: -
A47: + SBC (R&D Exp.) | B47: 917 | C47: 1216 | D47: 1536 | E47: 1889 | F47: - | G47: - | H47: - | I47: - | J47: - | K47: - | L47: - | M47: -
A48: Depreciation & Amort. | B48: - | C48: - | D48: - | E48: - | F48: - | G48: - | H48: - | I48: - | J48: - | K48: - | L48: - | M48: -
A49: Other Operating Expense/(Income) | B49: - | C49: - | D49: - | E49: - | F49: - | G49: - | H49: - | I49: - | J49: - | K49: - | L49: - | M49: -
A51: Other Operating Exp., Total | B51: 15305 | C51: 18034 | D51: 22396 | E51: 24239 | F51: 26842 | G51: 30941 | H51: 34462 | I51: 38668 | J51: 43887 | K51: 51345 | L51: 54847 | M51: 55013
...

Sheet BS
A5: Apple Inc. (NasdaqGS:AAPL) > Financials > Balance Sheet
A7: In Millions of the reported currency, except per share items. | B7: Template: | C7: Standard | E7: Restatement: | F7: Latest Filings
B8: Period Type: | C8: Annual | E8: Order: | F8: Latest on Right
B9: Currency: | C9: Reported Currency | E9: Conversion: | F9: Historical
B10: Units: | C10: S&P Capital IQ (Default) | E10: Decimals: | F10: Capital IQ (Default)
B11: Source: | C11: Capital IQ & Proprietary Data
A14: Balance Sheet
A15: Balance Sheet as of: | B15: 41545 | C15: 41909 | D15: Restated Sep-26-2015 | E15: 42637 | F15: 43008 | G15: Reclassified Sep-29-2018 | H15: 43736 | I15: 44100 | J15: 44464 | K15: 44828 | L15: 45199 | M15: 45290
A16: Currency | B16: USD | C16: USD | D16: USD | E16: USD | F16: USD | G16: USD | H16: USD | I16: USD | J16: USD | K16: USD | L16: USD | M16: USD
A17: ASSETS | P17: Net Debt Calculation | Q17: FY24Q1
A18: Cash And Equivalents | B18: 14259 | C18: 13844 | D18: 21120 | E18: 20484 | F18: 20289 | G18: 25913 | H18: 48844 | I18: 38016 | J18: 34940 | K18: 23646 | L18: 29965 | M18: 40760 | P18: Debt | Q18: =M111+M116+M137+M141 -> 106042
A19: = Cash and Cash Equivalents | B19: 14259 | C19: 13844 | D19: 21120 | E19: 20484 | F19: 20289 | G19: 25913 | H19: 48844 | I19: 38016 | J19: 34940 | K19: 23646 | L19: 29965 | M19: - | P19: Cash | Q19: =M26 -> 73100
A20: + Cash and Cash Equivalents | B20: - | C20: - | D20: - | E20: - | F20: - | G20: - | H20: - | I20: - | J20: - | K20: - | L20: - | M20: 40760 | P20: Net Debt | Q20: =Q18-Q19 -> 32942
A21: Short Term Investments | B21: 26287 | C21: 11233 | D21: 20481 | E21: 46671 | F21: 53892 | G21: 40388 | H21: 51713 | I21: 52927 | J21: 27699 | K21: 24658 | L21: 31590 | M21: 32340
A22: = Short-term Investments | B22: - | C22: - | D22: - | E22: - | F22: - | G22: - | H22: - | I22: - | J22: - | K22: - | L22: - | M22: 32340
A23: + Short-term Marketable Securities | B23: 26287 | C23: 11233 | D23: 20481 | E23: 46671 | F23: 53892 | G23: 40388 | H23: 51713 | I23: 52927 | J23: 27699 | K23: 24658 | L23: 31590 | M23: -
A24: Trading Asset Securities | B24: 44 | C24: 81 | D24: 394 | E24: - | F24: - | G24: - | H24: - | I24: - | J24: - | K24: - | L24: - | M24: -
A25: = Derivative Trading Asset Securities | B25: 44 | C25: 81 | D25: 394 | E25: - | F25: - | G25: - | H25: - | I25: - | J25: - | K25: - | L25: - | M25: -
A26: Total Cash & ST Investments | B26: 40590 | C26: 25158 | D26: 41995 | E26: 67155 | F26: 74181 | G26: 66301 | H26: 100557 | I26: 90943 | J26: 62639 | K26: 48304 | L26: 61555 | M26: 73100
A28: Accounts Receivable | B28: 13102 | C28: 17460 | D28: 16849 | E28: 15754 | F28: 17874 | G28: 23186 | H28: 22926 | I28: 16120 | J28: 26278 | K28: 28184 | L28: 29508 | M28: 23194
A29: = Accounts Receivables | B29: - | C29: - | D29: - | E29: - | F29: 17874 | G29: 23186 | H29: 22926 | I29: 16120 | J29: 26278 | K29: 28184 | L29: 29508 | M29: -
A30: + Allowance for Doubtful Accounts Receivable | B30: -99 | C30: -86 | D30: -63 | E30: -53 | F30: - | G30: - | H30: - | I30: - | J30: - | K30: - | L30: - | M30: -
A31: + Accounts Receivables | B31: 13102 | C31: 17460 | D31: 16849 | E31: 15754 | F31: - | G31: - | H31: - | I31: - | J31: - | K31: - | L31: - | M31: 23194
A32: - Allowance for Doubtful Accounts Receivable | B32: -99 | C32: -86 | D32: -63 | E32: -53 | F32: - | G32: - | H32: - | I32: - | J32: - | K32: - | L32: - | M32: -
A33: Other Receivables | B33: 7539 | C33: 9759 | D33: 13494 | E33: 13545 | F33: 17799 | G33: 25809 | H33: 22878 | I33: 21325 | J33: 25228 | K33: 32748 | L33: 31477 | M33: 26908
A34: = Other Receivables | B34: - | C34: - | D34: - | E34: - | F34: - | G34: - | H34: - | I34: - | J34: - | K34: - | L34: - | M34: 26908
A35: + Vendor non-trade receivables | B35: 7539 | C35: 9759 | D35: 13494 | E35: 13545 | F35: 17799 | G35: 25809 | H35: 22878 | I35: 21325 | J35: 25228 | K35: 32748 | L35: 31477 | M35: -
A36: Total Receivables | B36: 20641 | C36: 27219 | D36: 30343 | E36: 29299 | F36: 35673 | G36: 48995 | H36: 45804 | I36: 37445 | J36: 51506 | K36: 60932 | L36: 60985 | M36: 50102
A38: Inventory | B38: 1764 | C38: 2111 | D38: 2349 | E38: 2132 | F38: 4855 | G38: 3956 | H38: 4106 | I38: 4061 | J38: 6580 | K38: 4946 | L38: 6331 | M38: 6511
A39: = Inventories | B39: - | C39: 2111 | D39: 2349 | E39: 2132 | F39: 4855 | G39: 3956 | H39: 4106 | I39: 4061 | J39: 6580 | K39: 4946 | L39: 6331 | M39: -
A40: + Inventory | B40: - | C40: - | D40: - | E40: - | F40: - | G40: - | H40: - | I40: - | J40: - | K40: - | L40: - | M40: 6511
A41: + Inventories - Raw Materials | B41: 683 | C41: - | D41: - | E41: - | F41: - | G41: - | H41: - | I41: - | J41: - | K41: - | L41: - | M41: -
A42: + Inventories - Finished Goods | B42: 1081 | C42: - | D42: - | E42: - | F42: - | G42: - | H42: - | I42: - | J42: - | K42: - | L42: - | M42: -
A43: Deferred Tax Assets, Curr. | B43: 3453 | C43: 4318 | D43: - | E43: - | F43: - | G43: - | H43: - | I43: - | J43: - | K43: - | L43: - | M43: -
A44: = Deferred Tax Assets | B44: 3453 | C44: 4318 | D44: - | E44: - | F44: - | G44: - | H44: - | I44: - | J44: - | K44: - | L44: - | M44: -
A45: Restricted Cash | B45: - | C45: - | D45: - | E45: - | F45: - | G45: - | H45: 23 | I45: - | J45: - | K45: - | L45: - | M45: -
A46: = Restricted Cash | B46: - | C46: - | D46: - | E46: - | F46: - | G46: - | H46: 23 | I46: - | J46: - | K46: - | L46: - | M46: -
A47: Other Current Assets | B47: 6838 | C47: 9725 | D47: 14691 | E47: 8283 | F47: 13936 | G47: 12087 | H47: 12329 | I47: 11264 | J47: 14111 | K47: 21223 | L47: 14695 | M47: 13979
A48: = Other Current Assets | B48: - | C48: - | D48: - | E48: 8283 | F48: 13936 | G48: 12087 | H48: - | I48: 11264 | J48: 14111 | K48: 21223 | L48: 14695 | M48: -
A49: + Other Current Assets | B49: 6882 | C49: 9806 | D49: 15085 | E49: - | F49: - | G49: - | H49: 12352 | I49: - | J49: - | K49: - | L49: - | M49: 13979
...

Sheet CF
A5: Apple Inc. (NasdaqGS:AAPL) > Financials > Cash Flow
A7: In Millions of the reported currency, except per share items. | B7: Template: | C7: Standard | E7: Restatement: | F7: Latest Filings
B8: Period Type: | C8: Annual | E8: Order: | F8: Latest on Right
B9: Currency: | C9: Reported Currency | E9: Conversion: | F9: Historical
B10: Units: | C10: S&P Capital IQ (Default) | E10: Decimals: | F10: Capital IQ (Default)
B11: Source: | C11: Capital IQ & Proprietary Data
A14: Cash Flow
A15: For the Fiscal Period Ending | B15: 12 months Sep-28-2013 | C15: 12 months Sep-27-2014 | D15: 12 months Sep-26-2015 | E15: Restated 12 months Sep-24-2016 | F15: Restated 12 months Sep-30-2017 | G15: 12 months Sep-29-2018 | H15: 12 months Sep-28-2019 | I15: 12 months Sep-26-2020 | J15: 12 months Sep-25-2021 | K15: 12 months Sep-24-2022 | L15: 12 months Sep-30-2023 | M15: LTM 12 months Dec-30-2023
A16: Currency | B16: USD | C16: USD | D16: USD | E16: USD | F16: USD | G16: USD | H16: USD | I16: USD | J16: USD | K16: USD | L16: USD | M16: USD
A18: Net Income | B18: 37037 | C18: 39510 | D18: 53394 | E18: 45687 | F18: 48351 | G18: 59531 | H18: 55256 | I18: 57411 | J18: 94680 | K18: 99803 | L18: 96995 | M18: 100913
A19: Depreciation & Amort. | B19: 5797 | C19: 6846 | D19: 9957 | E19: 10505 | F19: 10157 | G19: 10903 | H19: 12547 | I19: 11056 | J19: 11284 | K19: 11104 | L19: 11519 | M19: 11451
A20: = Depreciation from Notes | B20: 5800 | C20: 6900 | D20: 9200 | E20: 8300 | F20: 8200 | G20: 9300 | H20: 11300 | I20: 9700 | J20: 9500 | K20: 8700 | L20: 8500 | M20: -
A21: + Depreciation and Amortization | B21: 6757 | C21: 7946 | D21: 11257 | E21: 10505 | F21: 10157 | G21: 10903 | H21: 12547 | I21: 11056 | J21: 11284 | K21: 11104 | L21: 11519 | M21: -
A22: - Depreciation from Notes | B22: 5800 | C22: 6900 | D22: 9200 | E22: 8300 | F22: 8200 | G22: 9300 | H22: 11300 | I22: 9700 | J22: 9500 | K22: 8700 | L22: 8500 | M22: -
A23: - Amortization of Intangible Assets | B23: 960 | C23: 1100 | D23: 1300 | E23: - | F23: - | G23: - | H23: - | I23: - | J23: - | K23: - | L23: - | M23: -
A24: Amort. of Goodwill and Intangibles | B24: 960 | C24: 1100 | D24: 1300 | E24: - | F24: - | G24: - | H24: - | I24: - | J24: - | K24: - | L24: - | M24: -
A25: = Amortization of Intangible Assets | B25: 960 | C25: 1100 | D25: 1300 | E25: - | F25: - | G25: - | H25: - | I25: - | J25: - | K25: - | L25: - | M25: -
A26: Depreciation & Amort., Total | B26: 6757 | C26: 7946 | D26: 11257 | E26: 10505 | F26: 10157 | G26: 10903 | H26: 12547 | I26: 11056 | J26: 11284 | K26: 11104 | L26: 11519 | M26: 11451
A28: Stock-Based Compensation | B28: 2253 | C28: 2863 | D28: 3586 | E28: 4210 | F28: 4840 | G28: 5340 | H28: 6068 | I28: 6829 | J28: 7906 | K28: 9038 | L28: 10833 | M28: 10925
A29: = Stock Based Compenation Expense | B29: 2253 | C29: 2863 | D29: 3586 | E29: 4210 | F29: 4840 | G29: 5340 | H29: 6068 | I29: 6829 | J29: 7906 | K29: 9038 | L29: 10833 | M29: -
A30: Other Operating Activities | B30: 1141 | C30: 2347 | D30: 1767 | E30: 5424 | F30: 5800 | G30: -33034 | H30: -992 | I30: -312 | J30: -4921 | K30: 1006 | L30: -2227 | M30: -2899
A31: = Others | B31: - | C31: - | D31: 385 | E31: 486 | F31: - | G31: -444 | H31: -652 | I31: -97 | J31: -4921 | K31: 1006 | L31: -2227 | M31: -
A32: + Deferred Income Tax Income/expense | B32: 1141 | C32: 2347 | D32: 1382 | E32: 4938 | F32: 5966 | G32: -32590 | H32: -340 | I32: -215 | J32: - | K32: - | L32: - | M32: -
A33: + Adjustments to Reconcile Net Income to Cash Generated By Operating Activities : Other | B33: - | C33: - | D33: - | E33: - | F33: -166 | G33: - | H33: - | I33: - | J33: - | K33: - | L33: - | M33: -
A34: Change in Acc. Receivable | B34: -2172 | C34: -4232 | D34: 417 | E34: 527 | F34: -2093 | G34: -5322 | H34: 245 | I34: 6917 | J34: -10125 | K34: -1823 | L34: -1688 | M34: 592
A35: = Accounts Receivable | B35: -2172 | C35: -4232 | D35: 417 | E35: 527 | F35: -2093 | G35: -5322 | H35: 245 | I35: 6917 | J35: -10125 | K35: -1823 | L35: -1688 | M35: -
A36: Change In Inventories | B36: -973 | C36: -76 | D36: -238 | E36: 217 | F36: -2723 | G36: 828 | H36: -289 | I36: -127 | J36: -2642 | K36: 1484 | L36: -1618 | M36: 52
A37: = Inventories | B37: -973 | C37: -76 | D37: -238 | E37: 217 | F37: -2723 | G37: 828 | H37: -289 | I37: -127 | J37: -2642 | K37: 1484 | L37: -1618 | M37: -
A38: Change in Acc. Payable | B38: 2340 | C38: 5938 | D38: 5001 | E38: 2117 | F38: 8966 | G38: 9175 | H38: -1923 | I38: -4062 | J38: 12326 | K38: 9448 | L38: -1889 | M38: -356
A39: = Accounts Payable | B39: 2340 | C39: 5938 | D39: 5001 | E39: 2117 | F39: 8966 | G39: 9175 | H39: -1923 | I39: -4062 | J39: 12326 | K39: 9448 | L39: -1889 | M39: -
A40: Change in Unearned Rev. | B40: 1459 | C40: 1460 | D40: 1042 | E40: -1554 | F40: -593 | G40: -3 | H40: -625 | I40: 2081 | J40: - | K40: - | L40: - | M40: -
A41: = Deferred Revenue | B41: 1459 | C41: 1460 | D41: 1042 | E41: -1554 | F41: -593 | G41: -3 | H41: -625 | I41: 2081 | J41: - | K41: - | L41: - | M41: -
A42: Change in Other Net Operating Assets | B42: 5824 | C42: 3957 | D42: 5040 | E42: -902 | F42: -8480 | G42: 30016 | H42: -896 | I42: 881 | J42: -4470 | K42: -7909 | L42: -1382 | M42: -4245
A43: = Other Current and Non-current Assets | B43: 1080 | C43: 167 | D43: -283 | E43: 1055 | F43: -5318 | G43: -423 | H43: 873 | I43: -9588 | J43: -8042 | K43: -6499 | L43: -5684 | M43: -
A44: + Other Current and Non-current Liabilities | B44: 4521 | C44: 6010 | D44: 9058 | E44: -1906 | F44: 1092 | G44: 38449 | H44: -4700 | I44: 8916 | J44: 7475 | K44: 6110 | L44: 3031 | M44: -
A45: + Vendor Non-trade Receivables | B45: 223 | C45: -2220 | D45: -3735 | E45: -51 | F45: -4254 | G45: -8010 | H45: 2931 | I45: 1553 | J45: -3903 | K45: -7520 | L45: 1271 | M45: -
A46: Cash from Ops. | B46: 53666 | C46: 59713 | D46: 81266 | E46: 66231 | F46: 64225 | G46: 77434 | H46: 69391 | I46: 80674 | J46: 104038 | K46: 122151 | L46: 110543 | M46: 116433
A48: Capital Expenditure | B48: -8165 | C48: -9571 | D48: -11247 | E48: -12734 | F48: -12451 | G48: -13313 | H48: -10495 | I48: -7309 | J48: -11085 | K48: -10708 | L48: -10959 | M48: -9564
A49: = Purchase of Property Plant, and Equipment | B49: -8165 | C49: -9571 | D49: -11247 | E49: -12734 | F49: -12451 | G49: -13313 | H49: -10495 | I49: -7309 | J49: -11085 | K49: -10708 | L49: -10959 | M49: -
A50: Cash Acquisitions | B50: -496 | C50: -3765 | D50: -343 | E50: -297 | F50: -329 | G50: -721 | H50: -624 | I50: -1524 | J50: - | K50: - | L50: - | M50: -
...

Sheet beta
A1: Daily | G1: Daily | J1: Weekly | P1: Weekly | S1: Average
A2: Date | B2: AAPL_Adj Close | C2: Log-return AAPL | D2: S&P 500 | E2: Log-return S&P 500 | G2: Volatility(AAPL) | H2: =_xlfn.STDEV.S(C4:C2518) -> 0.01788522 | J2: Date | K2: AAPL_Adj Close | L2: Log-return AAPL | M2: S&P 500 | N2: Log-return S&P 500 | P2: Volatility(AAPL) | Q2: =_xlfn.STDEV.S(L4:L524) -> 0.037303841 | S2: Average beta | T2: =AVERAGE(H5,Q5) -> 1.1948597
A3: 41641 | B3: 17.296661 | D3: 1831.98 | G3: Covariance | H3: =_xlfn.COVARIANCE.S(C4:C2518, E4:E2518) -> 0.00014931499 | J3: 41640 | K3: 16.887325 | M3: 1837.88 | P3: Covariance | Q3: =_xlfn.COVARIANCE.S(L4:L524,N4:N524) -> 0.00054878484 | S3: Average Volatility | T3: =AVERAGE(H7,Q7) -> 0.27646044
A4: 41642 | B4: 16.916723 | C4: =LN(B4/B3) -> -0.022210818 | D4: 1831.37 | E4: =LN(D4/D3) -> -0.00033302852 | G4: Variance(S&P) | H4: =_xlfn.VAR.S(E4:E2518) -> 0.00012573049 | J4: 41647 | K4: 17.085897 | L4: =LN(K4/K3) -> 0.011690046 | M4: 1838.88 | N4: =LN(M4/M3) -> 0.00054395719 | P4: Variance(S&P) | Q4: =_xlfn.VAR.S(N4:N524) -> 0.00045650675
A5: 41645 | B5: 17.008963 | C5: =LN(B5/B4) -> 0.0054377811 | D5: 1826.77 | E5: =LN(D5/D4) -> -0.0025149406 | G5: beta | H5: =H3/H4 -> 1.1875798 | J5: 41654 | K5: 17.169701 | L5: =LN(K5/K4) -> 0.0048928743 | M5: 1843.8 | N5: =LN(M5/M4) -> 0.0026719687 | P5: beta | Q5: =Q3/Q4 -> 1.2021396
A6: 41646 | B6: 16.887327 | C6: =LN(B6/B5) -> -0.0071769814 | D6: 1837.88 | E6: =LN(D6/D5) -> 0.0060633534 | J6: 41661 | K6: 15.838517 | L6: =LN(K6/K5) -> -0.080701502 | M6: 1792.5 | N6: =LN(M6/M5) -> -0.028217366
A7: 41647 | B7: 16.994272 | C7: =LN(B7/B6) -> 0.0063128871 | D7: 1837.49 | E7: =LN(D7/D6) -> -0.00021222353 | G7: Annualized Volatility | H7: =H2*SQRT(252) -> 0.28391907 | J7: 41668 | K7: 15.910119 | L7: =LN(K7/K6) -> 0.0045105636 | M7: 1755.2 | N7: =LN(M7/M6) -> -0.021028483 | P7: Annualized Volatility | Q7: =Q2*SQRT(52) -> 0.26900182
A8: 41648 | B8: 16.777254 | C8: =LN(B8/B7) -> -0.012852306 | D8: 1838.13 | E8: =LN(D8/D7) -> 0.00034824057 | J8: 41675 | K8: 16.759748 | L8: =LN(K8/K7) -> 0.052024737 | M8: 1819.75 | N8: =LN(M8/M7) -> 0.036116318
A9: 41649 | B9: 16.665308 | C9: =LN(B9/B8) -> -0.006694847 | D9: 1842.37 | E9: =LN(D9/D8) -> 0.0023040358 | J9: 41682 | K9: 17.175587 | L9: =LN(K9/K8) -> 0.024508956 | M9: 1840.76 | N9: =LN(M9/M8) -> 0.011479401
A10: 41652 | B10: 16.752541 | C10: =LN(B10/B9) -> 0.0052207548 | D10: 1819.2 | E10: =LN(D10/D9) -> -0.012655942 | J10: 41689 | K10: 16.422802 | L10: =LN(K10/K9) -> -0.04481828 | M10: 1845.12 | N10: =LN(M10/M9) -> 0.0023657862
A11: 41653 | B11: 17.08589 | C11: =LN(B11/B10) -> 0.019703028 | D11: 1838.88 | E11: =LN(D11/D10) -> 0.010759847 | J11: 41696 | K11: 16.71159 | L11: =LN(K11/K10) -> 0.017431756 | M11: 1873.91 | N11: =LN(M11/M10) -> 0.015482841
A12: 41654 | B12: 17.428938 | C12: =LN(B12/B11) -> 0.019878952 | D12: 1848.38 | E12: =LN(D12/D11) -> 0.0051528891 | J12: 41703 | K12: 16.864149 | L12: =LN(K12/K11) -> 0.009087517 | M12: 1867.63 | N12: =LN(M12/M11) -> -0.0033569097
A13: 41655 | B13: 17.331684 | C13: =LN(B13/B12) -> -0.0055956567 | D13: 1845.89 | E13: =LN(D13/D12) -> -0.0013480338 | J13: 41710 | K13: 16.716621 | L13: =LN(K13/K12) -> -0.0087865138 | M13: 1872.25 | N13: =LN(M13/M12) -> 0.0024706688
A14: 41656 | B14: 16.907028 | C14: =LN(B14/B13) -> -0.024806878 | D14: 1838.7 | E14: =LN(D14/D13) -> -0.0039027458 | J14: 41717 | K14: 17.144131 | L14: =LN(K14/K13) -> 0.025252405 | M14: 1865.62 | N14: =LN(M14/M13) -> -0.0035474786
A15: 41660 | B15: 17.169697 | C15: =LN(B15/B14) -> 0.015416634 | D15: 1843.8 | E15: =LN(D15/D14) -> 0.0027698592 | J15: 41724 | K15: 17.039057 | L15: =LN(K15/K14) -> -0.0061477198 | M15: 1885.52 | N15: =LN(M15/M14) -> 0.010610207
A16: 41661 | B16: 17.245996 | C16: =LN(B16/B15) -> 0.0044339729 | D16: 1844.86 | E16: =LN(D16/D15) -> 0.00057473447 | J16: 41731 | K16: 16.466213 | L16: =LN(K16/K15) -> -0.034197595 | M16: 1851.96 | N16: =LN(M16/M15) -> -0.017959107
A17: 41662 | B17: 17.392027 | C17: =LN(B17/B16) -> 0.0084318822 | D17: 1828.46 | E17: =LN(D17/D16) -> -0.0089293113 | J17: 41738 | K17: 16.293823 | L17: =LN(K17/K16) -> -0.010524506 | M17: 1842.98 | N17: =LN(M17/M16) -> -0.004860711
A18: 41663 | B18: 17.075893 | C18: =LN(B18/B17) -> -0.01834418 | D18: 1790.29 | E18: =LN(D18/D17) -> -0.021096465 | J18: 41745 | K18: 16.726053 | L18: =LN(K18/K17) -> 0.026181485 | M18: 1879.55 | N18: =LN(M18/M17) -> 0.01964856
A19: 41666 | B19: 17.214417 | C19: =LN(B19/B18) -> 0.0080795276 | D19: 1781.56 | E19: =LN(D19/D18) -> -0.0048882329 | J19: 41752 | K19: 18.633327 | L19: =LN(K19/K18) -> 0.10798419 | M19: 1878.33 | N19: =LN(M19/M18) -> -0.00064930229
... A524: 42397 | B524: 21.38743 | C524: =LN(B524/B523) -> 0.0071465747 | D524: 1893.36 | E524: =LN(D524/D523) -> 0.0055133325 | J524: 45287 | K524: 192.28464 | L524: =LN(K524/K523) -> -0.0026972976 | M524: 4769.83 | N524: =LN(M524/M523) -> -0.0010309517
A525: 42398 | B525: 22.126173 | C525: =LN(B525/B524) -> 0.03395784 | D525: 1940.24 | E525: =LN(D525/D524) -> 0.024458648
A526: 42401 | B526: 21.919329 | C526: =LN(B526/B525) -> -0.0093923561 | D526: 1939.38 | E526: =LN(D526/D525) -> -0.0004433424
A527: 42402 | B527: 21.476076 | C527: =LN(B527/B526) -> -0.020429279 | D527: 1903.03 | E527: =LN(D527/D526) -> -0.018920982
A528: 42403 | B528: 21.901146 | C528: =LN(B528/B527) -> 0.019599393 | D528: 1912.53 | E528: =LN(D528/D527) -> 0.0049796201
A529: 42404 | B529: 22.077126 | C529: =LN(B529/B528) -> 0.0080030857 | D529: 1915.45 | E529: =LN(D529/D528) -> 0.0015256091
A530: 42405 | B530: 21.487484 | C530: =LN(B530/B529) -> -0.027071424 | D530: 1880.05 | E530: =LN(D530/D529) -> -0.01865421
A531: 42408 | B531: 21.713743 | C531: =LN(B531/B530) -> 0.010474752 | D531: 1853.44 | E531: =LN(D531/D530) -> -0.014255
A532: 42409 | B532: 21.709164 | C532: =LN(B532/B531) -> -0.00021090251 | D532: 1852.21 | E532: =LN(D532/D531) -> -0.00066385117
A533: 42410 | B533: 21.544619 | C533: =LN(B533/B532) -> -0.0076083886 | D533: 1851.86 | E533: =LN(D533/D532) -> -0.00018898131
A534: 42411 | B534: 21.414351 | C534: =LN(B534/B533) -> -0.0060647822 | D534: 1829.08 | E534: =LN(D534/D533) -> -0.012377431
A535: 42412 | B535: 21.480627 | C535: =LN(B535/B534) -> 0.0030901544 | D535: 1864.78 | E535: =LN(D535/D534) -> 0.019329975
A536: 42416 | B536: 22.08626 | C536: =LN(B536/B535) -> 0.027804237 | D536: 1895.58 | E536: =LN(D536/D535) -> 0.016381777
... A2518: 45289 | B2518: 192.28464 | C2518: =LN(B2518/B2517) -> -0.0054388735 | D2518: 4769.83 | E2518: =LN(D2518/D2517) -> -0.002830473

Sheet WACC
A2: 10y Avg beta | B2: =beta!T2 -> 1.1948597
A4: rf | B4: 0.0443 | C4: 45366 | D4: (30-year US Treasury bond yield, found at treasury.gov)
A5: rm-rf(risk premium) | B5: 0.06
A6: r(E) | B6: =B4+B2*B5 -> 0.11599158 | C6: by CAPM: r(E) = rf + beta * risk premium
A7: r(D) | B7: 0.05026 | C7: 45366 | D7: YTW of 2053/5/10 AAPL corporate bond rated AA+
A9: Equity Value(Market Cap) | B9: ='Key Stats'!B53 -> 2665577.5 | C9: 45366
A10: Net Debt | B10: =BS!Q20 -> 32942 | C10: FY24Q1
A12: E/V | B12: =B9/(B9+B10) -> 0.98779257
A13: D/V | B13: =B10/(B9+B10) -> 0.012207434
A15: Effective Tax Rate | B15: =IS!O84 -> 0.1491958 | C15: 5-yr avg
A17: WACC | B17: =B12*B6+B13*B7*(1-B15) -> 0.11509763

Sheet Segment_Q
B1: FY1Q15 | C1: FY2Q15 | D1: FY3Q15 | E1: FY4Q15 | F1: FY1Q16 | G1: FY2Q16 | H1: FY3Q16 | I1: FY4Q16 | J1: FY1Q17 | K1: FY2Q17 | L1: FY3Q17 | M1: FY4Q17 | N1: FY1Q18 | O1: FY2Q18 | P1: FY3Q18 | Q1: FY4Q18 | R1: FY1Q19 | S1: FY2Q19 | T1: FY3Q19 | U1: FY4Q19 | V1: FY1Q20 | W1: FY2Q20 | X1: FY3Q20 | Y1: FY4Q20 | Z1: FY1Q21 | AA1: FY2Q21 | AB1: FY3Q21 | AC1: FY4Q21 | AD1: FY1Q22 | AE1: FY2Q22 | AF1: FY3Q22 | AG1: FY4Q22 | AH1: FY1Q23 | AI1: FY2Q23 | AJ1: FY3Q23 | AK1: FY4Q23 | AL1: FY1Q24 | AM1: FY2Q24E | AN1: FY3Q24E | AO1: FY4Q24E | AP1: FY1Q25E | AQ1: FY2Q25E | AR1: FY3Q25E | AS1: FY4Q25E
A2: iPhone | B2: 51182 | C2: 40282 | D2: 31368 | E2: ='[1]Segment Sales-Annual'!F2-SUM('[1]Segment Sales-Qty'!B2:D2) -> 32209 | F2: 51635 | G2: 32857 | H2: 24048 | I2: ='[1]Segment Sales-Annual'!G2-SUM('[1]Segment Sales-Qty'!F2:H2) -> 28160 | J2: 54378 | K2: 33249 | L2: 24846 | M2: ='[1]Segment Sales-Annual'!H2-SUM('[1]Segment Sales-Qty'!J2:L2) -> 26864 | N2: 61104 | O2: 37559 | P2: 29470 | Q2: ='[1]Segment Sales-Annual'!I2-SUM('[1]Segment Sales-Qty'!N2:P2) -> 36755 | R2: 51982 | S2: 31051 | T2: 25986 | U2: ='[1]Segment Sales-Annual'!J2-SUM('[1]Segment Sales-Qty'!R2:T2) -> 33362 | V2: 55957 | W2: 28962 | X2: 26418 | Y2: ='[1]Segment Sales-Annual'!K2-SUM('[1]Segment Sales-Qty'!V2:X2) -> 26444 | Z2: 65597 | AA2: 47938 | AB2: 39570 | AC2: ='[1]Segment Sales-Annual'!L2-SUM('[1]Segment Sales-Qty'!Z2:AB2) -> 38868 | AD2: 71628 | AE2: 50570 | AF2: 40665 | AG2: 42626 | AH2: 65775 | AI2: 51334 | AJ2: 39669 | AK2: =Segment_A!N2-SUM(Segment_Q!AH2:AJ2) -> 43805 | AL2: 69702 | AM2: =AL2*(1+AM3) -> 52276.5 | AN2: =AM2*(1+AN3) -> 43403.911 | AO2: =AN2*(1+AO3) -> 47046.147 | AP2: =AO2*(1+AP3) -> 78265.744 | AQ2: =AP2*(1+AQ3) -> 54548.546 | AR2: =AQ2*(1+AR3) -> 45218.271 | AS2: =AR2*(1+AS3) -> 47204.66
A3: QoQ | C3: =C2/B2-1 -> -0.2129655 | D3: =D2/C2-1 -> -0.22128991 | E3: =E2/D2-1 -> 0.026810763 | F3: =F2/E2-1 -> 0.60312335 | G3: =G2/F2-1 -> -0.36366805 | H3: =H2/G2-1 -> -0.26810117 | I3: =I2/H2-1 -> 0.17099135 | J3: =J2/I2-1 -> 0.93103693 | ... M3: =M2/L2-1 -> 0.081220317 | O3: =O2/N2-1 -> -0.38532666 | P3: =P2/O2-1 -> -0.21536782 | Q3: =Q2/P2-1 -> 0.24720054 | R3: =R2/Q2-1 -> 0.41428377 | S3: =S2/R2-1 -> -0.40265861 | T3: =T2/S2-1 -> -0.16311874 | U3: =U2/T2-1 -> 0.28384515 | V3: =V2/U2-1 -> 0.67726755 | ... AL3: =AL2/AK2-1 -> 0.59118822 | AM3: =-25% -> -0.25 | AN3: =AVERAGE(AJ3,AF3,AB3,X3,T3) -> -0.16972424 | AO3: =AVERAGE(AK3,AG3,AC3,Y3,U3) -> 0.083914935 | AP3: =AVERAGE(AL3,AH3,AD3,V3) -> 0.6635952 | AQ3: =AVERAGE(AM3,AI3,AE3,AA3,W3) -> -0.30303421 | AR3: =AVERAGE(AN3,AJ3,AF3,AB3,X3) -> -0.17104534 | AS3: =AVERAGE(AO3,AK3,AG3,AC3,Y3) -> 0.043928892
A4: YoY | F4: =F2/B2-1 -> 0.0088507678 | G4: =G2/C2-1 -> -0.18432551 | H4: =H2/D2-1 -> -0.23335884 | I4: =I2/E2-1 -> -0.12571021 | J4: =J2/F2-1 -> 0.053122882 | K4: =K2/G2-1 -> 0.011930487 | L4: =L2/H2-1 -> 0.033183633 | M4: =M2/I2-1 -> -0.046022727 | R4: =R2/N2-1 -> -0.14928646 | S4: =S2/O2-1 -> -0.17327405 | T4: =T2/P2-1 -> -0.11822192 | U4: =U2/Q2-1 -> -0.092313971 | V4: =V2/R2-1 -> 0.076468778 | W4: =W2/S2-1 -> -0.067276416 | X4: =X2/T2-1 -> 0.016624336 | Y4: =Y2/U2-1 -> -0.20736167 | ... AS4: =AS2/AO2-1 -> 0.0033693088
A5: Proportion | B5: =B2/B$32 -> 0.68609499 | C5: =C2/C$32 -> 0.69439752 | D5: =D2/D$32 -> 0.63235561 | E5: =E2/E$32 -> 0.62540533 | F5: =F2/F$32 -> 0.68055409 | G5: =G2/G$32 -> 0.64990011 | H5: =H2/H$32 -> 0.56773219 | I5: =I2/I$32 -> 0.60104158 | ... AS5: =AS2/AS$32 -> 0.45117803
A7: Mac | B7: 6944 | C7: 5615 | D7: 6030 | E7: ='[1]Segment Sales-Annual'!F3-SUM('[1]Segment Sales-Qty'!B7:D7) -> 6882 | F7: 6746 | G7: 5107 | H7: 5239 | I7: ='[1]Segment Sales-Annual'!G3-SUM('[1]Segment Sales-Qty'!F7:H7) -> 5739 | J7: 7244 | K7: 5844 | L7: 5592 | M7: ='[1]Segment Sales-Annual'!H3-SUM('[1]Segment Sales-Qty'!J7:L7) -> 6889 | N7: 6824 | O7: 5776 | P7: 5258 | Q7: ='[1]Segment Sales-Annual'!I3-SUM('[1]Segment Sales-Qty'!N7:P7) -> 7340 | R7: 7416 | S7: 5513 | T7: 5820 | U7: ='[1]Segment Sales-Annual'!J3-SUM('[1]Segment Sales-Qty'!R7:T7) -> 6991 | V7: 7160 | W7: 5351 | X7: 7079 | Y7: ='[1]Segment Sales-Annual'!K3-SUM('[1]Segment Sales-Qty'!V7:X7) -> 9032 | Z7: 8675 | AA7: 9102 | AB7: 8235 | AC7: ='[1]Segment Sales-Annual'!L3-SUM('[1]Segment Sales-Qty'!Z7:AB7) -> 9178 | AD7: 10852 | AE7: 10435 | AF7: 7382 | AG7: 11508 | AH7: 7735 | AI7: 7168 | AJ7: 6840 | AK7: =Segment_A!N3-SUM(Segment_Q!AH7:AJ7) -> 7614 | AL7: 7780 | AM7: =AL7*(1+AM8) -> 6890.3285 | AN7: =AM7*(1+AN8) -> 6814.5777 | AO7: =AN7*(1+AO8) -> 8536.8742 | AP7: =AO7*(1+AP8) -> 8299.521 | AQ7: =AP7*(1+AQ8) -> 7586.5678 | AR7: =AQ7*(1+AR8) -> 7401.9877 | AS7: =AR7*(1+AS8) -> 9349.0358
A8: QoQ | C8: =C7/B7-1 -> -0.19138825 | D8: =D7/C7-1 -> 0.073909172 | E8: =E7/D7-1 -> 0.14129353 | F8: =F7/E7-1 -> -0.019761697 | G8: =G7/F7-1 -> -0.24295879 | H8: =H7/G7-1 -> 0.025846877 | I8: =I7/H7-1 -> 0.095438061 | J8: =J7/I7-1 -> 0.26224081 | ... M8: =M7/L7-1 -> 0.23193848 | O8: =O7/N7-1 -> -0.15357562 | P8: =P7/O7-1 -> -0.08968144 | Q8: =Q7/P7-1 -> 0.39596805 | R8: =R7/Q7-1 -> 0.010354223 | S8: =S7/R7-1 -> -0.25660734 | T8: =T7/S7-1 -> 0.055686559 | U8: =U7/T7-1 -> 0.20120275 | V8: =V7/U7-1 -> 0.024173938 | ... AL8: =AL7/AK7-1 -> 0.021801944 | AM8: =AVERAGE(AI8,AE8,AA8,W8,S8) -> -0.11435367 | AN8: =AVERAGE(AJ8,AF8,AB8,X8,T8) -> -0.010993788 | AO8: =AVERAGE(AK8,AG8,AC8,Y8,U8) -> 0.25273708 | AP8: =AVERAGE(AL8,AH8,AD8,Z8,V8) -> -0.02780329 | AQ8: =AVERAGE(AM8,AI8,AE8,AA8,W8) -> -0.085902932 | AR8: =AVERAGE(AN8,AJ8,AF8,AB8,X8) -> -0.024329857 | AS8: =AVERAGE(AO8,AK8,AG8,AC8,Y8) -> 0.26304395
A9: YoY | F9: =F7/B7-1 -> -0.028513825 | G9: =G7/C7-1 -> -0.09047195 | H9: =H7/D7-1 -> -0.13117745 | I9: =I7/E7-1 -> -0.16608544 | J9: =J7/F7-1 -> 0.073821524 | K9: =K7/G7-1 -> 0.14431173 | L9: =L7/H7-1 -> 0.067379271 | M9: =M7/I7-1 -> 0.20038334 | R9: =R7/N7-1 -> 0.086752638 | S9: =S7/O7-1 -> -0.045533241 | T9: =T7/P7-1 -> 0.10688475 | U9: =U7/Q7-1 -> -0.047547684 | V9: =V7/R7-1 -> -0.034519957 | W9: =W7/S7-1 -> -0.02938509 | X9: =X7/T7-1 -> 0.21632302 | Y9: =Y7/U7-1 -> 0.29194679 | ... AS9: =AS7/AO7-1 -> 0.095135712
A10: Proportion | B10: =B7/B$32 -> 0.093084358 | C10: =C7/C$32 -> 0.096793656 | D10: =D7/D$32 -> 0.12156033 | E10: =E7/E$32 -> 0.13362847 | F10: =F7/F$32 -> 0.088912906 | G10: =G7/G$32 -> 0.1010147 | H10: =H7/H$32 -> 0.12368384 | I10: =I7/I$32 -> 0.1224921 | ... AS10: =AS7/AS$32 -> 0.089357269
A12: iPad | B12: 8985 | C12: 5428 | D12: 4538 | E12: ='[1]Segment Sales-Annual'!F4-SUM('[1]Segment Sales-Qty'!B12:D12) -> 4276 | F12: 7084 | G12: 4413 | H12: 4876 | I12: ='[1]Segment Sales-Annual'!G4-SUM('[1]Segment Sales-Qty'!F12:H12) -> 4255 | J12: 5533 | K12: 3889 | L12: 4969 | M12: ='[1]Segment Sales-Annual'!H4-SUM('[1]Segment Sales-Qty'!J12:L12) -> 4411 | N12: 5755 | O12: 4008 | P12: 4634 | Q12: ='[1]Segment Sales-Annual'!I4-SUM('[1]Segment Sales-Qty'!N12:P12) -> 3983 | R12: 6729 | S12: 4872 | T12: 5023 | U12: ='[1]Segment Sales-Annual'!J4-SUM('[1]Segment Sales-Qty'!R12:T12) -> 4656 | V12: 5977 | W12: 4368 | X12: 6582 | Y12: ='[1]Segment Sales-Annual'!K4-SUM('[1]Segment Sales-Qty'!V12:X12) -> 6797 | Z12: 8435 | AA12: 7807 | AB12: 7368 | AC12: ='[1]Segment Sales-Annual'!L4-SUM('[1]Segment Sales-Qty'!Z12:AB12) -> 8252 | AD12: 7248 | AE12: 7646 | AF12: 7224 | AG12: 7174 | AH12: 9396 | AI12: 6670 | AJ12: 5791 | AK12: =Segment_A!N4-SUM(Segment_Q!AH12:AJ12) -> 6443 | AL12: 7023 | AM12: =AL12*(1+AM13) -> 5822.3034 | AN12: =AM12*(1+AN13) -> 6165.4159 | AO12: =AN12*(1+AO13) -> 6393.8401 | AP12: =AO12*(1+AP13) -> 7420.4234 | AQ12: =AP12*(1+AQ13) -> 6307.6145 | AR12: =AQ12*(1+AR13) -> 6714.5704 | AS12: =AR12*(1+AS13) -> 7111.2128
A13: QoQ | C13: =C12/B12-1 -> -0.39588203 | D13: =D12/C12-1 -> -0.16396463 | E13: =E12/D12-1 -> -0.057734685 | F13: =F12/E12-1 -> 0.65668849 | G13: =G12/F12-1 -> -0.37704687 | H13: =H12/G12-1 -> 0.10491729 | I13: =I12/H12-1 -> -0.12735849 | J13: =J12/I12-1 -> 0.30035253 | ... M13: =M12/L12-1 -> -0.11229624 | O13: =O12/N12-1 -> -0.30356212 | P13: =P12/O12-1 -> 0.15618762 | Q13: =Q12/P12-1 -> -0.14048338 | R13: =R12/Q12-1 -> 0.68943008 | S13: =S12/R12-1 -> -0.27596968 | T13: =T12/S12-1 -> 0.030993432 | U13: =U12/T12-1 -> -0.073063906 | V13: =V12/U12-1 -> 0.28371993 | ... AL13: =AL12/AK12-1 -> 0.090020177 | AM13: =AVERAGE(AI13,AE13,AA13,W13,S13) -> -0.17096634 | AN13: =AVERAGE(AJ13,AF13,AB13,X13,T13) -> 0.058930722 | AO13: =AVERAGE(AK13,AG13,AC13,Y13,U13) -> 0.03704927 | AP13: =AVERAGE(AL13,AH13,AD13,Z13,V13) -> 0.16055818 | AQ13: =AVERAGE(AM13,AI13,AE13,AA13,W13) -> -0.14996568 | AR13: =AVERAGE(AN13,AJ13,AF13,AB13,X13) -> 0.06451818 | AS13: =AVERAGE(AO13,AK13,AG13,AC13,Y13) -> 0.059071905
A14: YoY | F14: =F12/B12-1 -> -0.21157485 | G14: =G12/C12-1 -> -0.18699337 | H14: =H12/D12-1 -> 0.074482151 | I14: =I12/E12-1 -> -0.0049111319 | J14: =J12/F12-1 -> -0.2189441 | K14: =K12/G12-1 -> -0.11874009 | L14: =L12/H12-1 -> 0.019073011 | M14: =M12/I12-1 -> 0.03666275 | R14: =R12/N12-1 -> 0.16924414 | S14: =S12/O12-1 -> 0.21556886 | T14: =T12/P12-1 -> 0.083944756 | U14: =U12/Q12-1 -> 0.16896811 | V14: =V12/R12-1 -> -0.11175509 | W14: =W12/S12-1 -> -0.10344828 | X14: =X12/T12-1 -> 0.31037229 | Y14: =Y12/U12-1 -> 0.45983677 | ... AS14: =AS12/AO12-1 -> 0.11219748
A15: Proportion | B15: =B12/B$32 -> 0.12044397 | C15: =C12/C$32 -> 0.093570074 | D15: =D12/D$32 -> 0.091482713 | E15: =E12/E$32 -> 0.083027514 | F15: =F12/F$32 -> 0.093367777 | G15: =G12/G$32 -> 0.087287616 | H15: =H12/H$32 -> 0.11511403 | I15: =I12/I$32 -> 0.090817895 | ... AS15: =AS12/AS$32 -> 0.067968352
A17: Wearables, Home and Accessories | M17: =M32-(M2+M7+M12+M22) -> 3194 | N17: 5481 | O17: 3944 | P17: 3733 | Q17: ='[1]Segment Sales-Annual'!I5-SUM('[1]Segment Sales-Qty'!N17:P17) -> 4223 | R17: 7308 | S17: 5129 | T17: 5525 | U17: ='[1]Segment Sales-Annual'!J5-SUM('[1]Segment Sales-Qty'!R17:T17) -> 6520 | V17: 10010 | W17: 6284 | X17: 6450 | Y17: ='[1]Segment Sales-Annual'!K5-SUM('[1]Segment Sales-Qty'!V17:X17) -> 7876 | Z17: 12971 | AA17: 7836 | AB17: 8775 | AC17: ='[1]Segment Sales-Annual'!L5-SUM('[1]Segment Sales-Qty'!Z17:AB17) -> 8785 | AD17: 14701 | AE17: 8806 | AF17: 8084 | AG17: 9650 | AH17: 13482 | AI17: 8757 | AJ17: 8284 | AK17: =Segment_A!N5-SUM(Segment_Q!AH17:AJ17) -> 9322 | AL17: 11953 | AM17: =AL17*(1+AM18)+AM39 -> 8347.5162 | AN17: =AM17*(1+AN18)+AN39 -> 8863.5183 | AO17: =AN17*(1+AO18)+AO39 -> 10512.228 | AP17: =AO17*(1+AP18)+AP39 -> 16211.786 | AQ17: =AP17*(1+AQ18) -> 10106.042 | AR17: =AQ17*(1+AR18) -> 10162.1 | AS17: =AR17*(1+AS18) -> 11555.343
A18: QoQ | O18: =O17/N17-1 -> -0.28042328 | P18: =P17/O17-1 -> -0.053498986 | Q18: =Q17/P17-1 -> 0.13126172 | R18: =R17/Q17-1 -> 0.73052332 | S18: =S17/R17-1 -> -0.29816639 | T18: =T17/S17-1 -> 0.077208033 | U18: =U17/T17-1 -> 0.1800905 | V18: =V17/U17-1 -> 0.53527607 | ... AL18: =AL17/AK17-1 -> 0.28223557 | AM18: =AVERAGE(AI18,AE18,AA18,W18,S18) -> -0.36354754 | AN18: =AVERAGE(AJ18,AF18,AB18,X18,T18) -> 0.017490478 | AO18: =AVERAGE(AK18,AG18,AC18,Y18,U18) -> 0.14426663 | AP18: =AVERAGE(AL18,AH18,AD18,Z18,V18) -> 0.50698653 | AQ18: =AVERAGE(AM18,AI18,AE18,AA18,W18) -> -0.37662377 | AR18: =AVERAGE(AN18,AJ18,AF18,AB18,X18) -> 0.0055469672 | AS18: =AVERAGE(AO18,AK18,AG18,AC18,Y18) -> 0.13710185
A19: YoY | R19: =R17/N17-1 -> 0.33333333 | S19: =S17/O17-1 -> 0.30045639 | T19: =T17/P17-1 -> 0.48004286 | U19: =U17/Q17-1 -> 0.54392612 | V19: =V17/R17-1 -> 0.3697318 | W19: =W17/S17-1 -> 0.2251901 | X19: =X17/T17-1 -> 0.16742081 | Y19: =Y17/U17-1 -> 0.20797546 | ... AS19: =AS17/AO17-1 -> 0.099228695
A20: Proportion | N20: =N17/N32 -> 0.062077401 | O20: =O17/O32 -> 0.064510853 | P20: =P17/P32 -> 0.070083545 | Q20: =Q17/Q32 -> 0.067138315 | R20: =R17/R32 -> 0.086680109 | S20: =S17/S32 -> 0.08840817 | T20: =T17/T32 -> 0.10267799 | U20: =U17/U32 -> 0.10181137 | ... AL20: =AL17/AL32 -> 0.099962367 | AM20: =AM17/AM$32 -> 0.085733085 | AN20: =AN17/AN$32 -> 0.099150984 | AO20: =AO17/AO$32 -> 0.10731253 | AP20: =AP17/AP$32 -> 0.11822861 | AQ20: =AQ17/AQ$32 -> 0.094923997 | AR20: =AR17/AR$32 -> 0.1041482 | AS20: =AS17/AS$32 -> 0.11044496
A22: Services | B22: 4799 | C22: 4996 | D22: 5028 | E22: ='[1]Segment Sales-Annual'!F6-SUM('[1]Segment Sales-Qty'!B22:D22) -> 5086 | F22: 6056 | G22: 5991 | H22: 5976 | I22: ='[1]Segment Sales-Annual'!G6-SUM('[1]Segment Sales-Qty'!F22:H22) -> 6325 | J22: 7172 | K22: 7041 | L22: 7266 | M22: ='[1]Segment Sales-Annual'!H6-SUM('[1]Segment Sales-Qty'!J22:L22) -> 11221 | N22: 9129 | O22: 9850 | P22: 10170 | Q22: ='[1]Segment Sales-Annual'!I6-SUM('[1]Segment Sales-Qty'!N22:P22) -> 10599 | R22: 10875 | S22: 11450 | T22: 11455 | U22: ='[1]Segment Sales-Annual'!J6-SUM('[1]Segment Sales-Qty'!R22:T22) -> 12511 | V22: 12715 | W22: 13348 | X22: 13156 | Y22: ='[1]Segment Sales-Annual'!K6-SUM('[1]Segment Sales-Qty'!V22:X22) -> 14549 | Z22: 15761 | AA22: 16901 | AB22: 17486 | AC22: ='[1]Segment Sales-Annual'!L6-SUM('[1]Segment Sales-Qty'!Z22:AB22) -> 18277 | AD22: 19516 | AE22: 19821 | AF22: 19604 | AG22: 19188 | AH22: 20766 | AI22: 20907 | AJ22: 21213 | AK22: =Segment_A!N6-SUM(Segment_Q!AH22:AJ22) -> 22314 | AL22: 23117 | AM22: =AL22*(1+AM23) -> 24029.686 | AN22: =AM22*(1+AN23) -> 24146.731 | AO22: =AN22*(1+AO23) -> 25469.915 | AP22: =AO22*(1+AP23) -> 26924.887 | AQ22: =AP22*(1+AQ23) -> 27915.796 | AR22: =AQ22*(1+AR23) -> 28076.525 | AS22: =AR22*(1+AS23) -> 29405.101
A23: QoQ | C23: =C22/B22-1 -> 0.041050219 | D23: =D22/C22-1 -> 0.0064051241 | E23: =E22/D22-1 -> 0.011535402 | F23: =F22/E22-1 -> 0.19071962 | G23: =G22/F22-1 -> -0.010733157 | H23: =H22/G22-1 -> -0.0025037556 | I23: =I22/H22-1 -> 0.058400268 | J23: =J22/I22-1 -> 0.13391304 | ... M23: =M22/L22-1 -> 0.54431599 | O23: =O22/N22-1 -> 0.078979078 | P23: =P22/O22-1 -> 0.03248731 | Q23: =Q22/P22-1 -> 0.042182891 | R23: =R22/Q22-1 -> 0.026040192 | S23: =S22/R22-1 -> 0.052873563 | T23: =T22/S22-1 -> 0.00043668122 | U23: =U22/T22-1 -> 0.092186818 | V23: =V22/U22-1 -> 0.016305651 | ... AL23: =AL22/AK22-1 -> 0.035986376 | AM23: =AVERAGE(AI23,AE23,AA23,W23,S23) -> 0.039481173 | AN23: =AVERAGE(AJ23,AF23,AB23,X23,T23) -> 0.0048708204 | AO23: =AVERAGE(AK23,AG23,AC23,Y23,U23) -> 0.054797646 | AP23: =AVERAGE(AL23,AH23,AD23,Z23,V23) -> 0.057125148 | AQ23: =AVERAGE(AM23,AI23,AE23,AA23,W23) -> 0.036802695 | AR23: =AVERAGE(AN23,AJ23,AF23,AB23,X23) -> 0.0057576483 | AS23: =AVERAGE(AO23,AK23,AG23,AC23,Y23) -> 0.047319812
A24: YoY | F24: =F22/B22-1 -> 0.26192957 | G24: =G22/C22-1 -> 0.19915933 | H24: =H22/D22-1 -> 0.18854415 | I24: =I22/E22-1 -> 0.24360991 | J24: =J22/F22-1 -> 0.18428005 | K24: =K22/G22-1 -> 0.17526289 | L24: =L22/H22-1 -> 0.21586345 | M24: =M22/I22-1 -> 0.77407115 | R24: =R22/N22-1 -> 0.19125863 | S24: =S22/O22-1 -> 0.16243655 | T24: =T22/P22-1 -> 0.12635202 | U24: =U22/Q22-1 -> 0.18039438 | V24: =V22/R22-1 -> 0.1691954 | W24: =W22/S22-1 -> 0.16576419 | X24: =X22/T22-1 -> 0.14849411 | Y24: =Y22/U22-1 -> 0.16289665 | ... AS24: =AS22/AO22-1 -> 0.15450332
A25: Proportion | B25: =B22/B$32 -> 0.064330621 | C25: =C22/C$32 -> 0.086123082 | D25: =D22/D$32 -> 0.10136075 | E25: =E22/E$32 -> 0.098755364 | F25: =F22/F$32 -> 0.079818642 | G25: =G22/G$32 -> 0.11849991 | H25: =H22/H$32 -> 0.14108315 | I25: =I22/I$32 -> 0.13499957 | ... AS25: =AS22/AS$32 -> 0.28105139
A27: Other Products | B27: 2689 | C27: 1689 | D27: 2641 | E27: ='[1]Segment Sales-Annual'!F7-SUM('[1]Segment Sales-Qty'!B27:D27) -> 3048 | F27: 4351 | G27: 2189 | H27: 2219 | I27: ='[1]Segment Sales-Annual'!G7-SUM('[1]Segment Sales-Qty'!F27:H27) -> 2373 | J27: 4024 | K27: 2873 | L27: 2735
A28: QoQ | C28: =C27/B27-1 -> -0.37188546 | D28: =D27/C27-1 -> 0.56364713 | E28: =E27/D27-1 -> 0.15410829 | F28: =F27/E27-1 -> 0.42749344 | G28: =G27/F27-1 -> -0.49689726 | H28: =H27/G27-1 -> 0.013704888 | I28: =I27/H27-1 -> 0.069400631 | J28: =J27/I27-1 -> 0.69574378 | ... L28: =L27/K27-1 -> -0.048033415
A29: YoY | F29: =F27/B27-1 -> 0.61807363 | G29: =G27/C27-1 -> 0.29603316 | H29: =H27/D27-1 -> -0.15978796 | I29: =I27/E27-1 -> -0.22145669 | J29: =J27/F27-1 -> -0.075155137 | K29: =K27/G27-1 -> 0.31247145 | L29: =L27/H27-1 -> 0.23253718
A30: Proportion | B30: =B27/B$32 -> 0.03604606 | C30: =C27/C$32 -> 0.02911567 | D30: =D27/D$32 -> 0.053240601 | E30: =E27/E$32 -> 0.059183317 | F30: =F27/F$32 -> 0.057346584 | G30: =G27/G$32 -> 0.043297664 | H30: =H27/H$32 -> 0.052386798 | I30: =I27/I$32 -> 0.050648852 | ... L30: =L27/L$32 -> 0.060231677
A32: Net Sales | B32: =B2+B7+B12+B17+B22+B27 -> 74599 | C32: =C2+C7+C12+C17+C22+C27 -> 58010 | D32: =D2+D7+D12+D17+D22+D27 -> 49605 | E32: =E2+E7+E12+E17+E22+E27 -> 51501 | F32: =F2+F7+F12+F17+F22+F27 -> 75872 | G32: =G2+G7+G12+G17+G22+G27 -> 50557 | H32: =H2+H7+H12+H17+H22+H27 -> 42358 | I32: =I2+I7+I12+I17+I22+I27 -> 46852 | ... L32: =L2+L7+L12+L17+L22+L27 -> 45408 | M32: ='[1]Segment Sales-Annual'!H8-SUM('[1]Segment Sales-Qty'!J32:L32) -> 52579 | N32: =N2+N7+N12+N17+N22+N27 -> 88293 | O32: =O2+O7+O12+O17+O22+O27 -> 61137 | P32: =P2+P7+P12+P17+P22+P27 -> 53265 | Q32: =Q2+Q7+Q12+Q17+Q22+Q27 -> 62900 | R32: =R2+R7+R12+R17+R22+R27 -> 84310 | S32: =S2+S7+S12+S17+S22+S27 -> 58015 | T32: =T2+T7+T12+T17+T22+T27 -> 53809 | U32: =U2+U7+U12+U17+U22+U27 -> 64040 | ... AS32: =AS2+AS7+AS12+AS17+AS22+AS27 -> 104625.35
A33: QoQ | O33: =O32/N32-1 -> -0.30756685 | P33: =P32/O32-1 -> -0.12876 | Q33: =Q32/P32-1 -> 0.18088801 | R33: =R32/Q32-1 -> 0.34038156 | S33: =S32/R32-1 -> -0.31188471 | T33: =T32/S32-1 -> -0.072498492 | U33: =U32/T32-1 -> 0.19013548 | V33: =V32/U32-1 -> 0.43377577 | ... AS33: =AS32/AR32-1 -> 0.072272708
A34: YoY | R34: =R32/N32-1 -> -0.045111164 | S34: =S32/O32-1 -> -0.051065639 | T34: =T32/P32-1 -> 0.010213086 | U34: =U32/Q32-1 -> 0.018124006 | V34: =V32/R32-1 -> 0.089064168 | W34: =W32/S32-1 -> 0.0051366026 | X34: =X32/T32-1 -> 0.10920106 | Y34: =Y32/U32-1 -> 0.010274828 | ... AS34: =AS32/AO32-1 -> 0.068052431
AL36: Vision Pro
AL37: Shipment(mn) | AM37: 0.2 | AN37: 0.1 | AO37: 0.1 | AP37: 0.1 | AQ37: (Consensus shipment of appox. 500k in CY2024, with FY2Q24 200k)
AL38: Unit Price(USD) | AM38: 3700 | AN38: 3700 | AO38: 3700 | AP38: 3700 | AQ38: (Avg Price: take 512GB)
AL39: Rev Contribution | AM39: =AM37*AM38 -> 740 | AN39: =AN37*AN38 -> 370 | AO39: =AO37*AO38 -> 370 | AP39: =AP37*AP38 -> 370 | AQ39: (Added to WH&A)
U41: 4Q19 | V41: 1Q20 | W41: 2Q20 | X41: 3Q20 | Y41: 4Q20 | Z41: 1Q21 | AA41: 2Q21 | AB41: 3Q21 | AC41: 4Q21 | AD41: 1Q22 | AE41: 2Q22 | AF41: 3Q22 | AG41: 4Q22 | AH41: 1Q23 | AI41: 2Q23 | AJ41: 3Q23 | AK41: 4Q23 | AL41: 1Q24
T42: Service Rev | U42: 12511 | V42: 12715 | W42: 13348 | X42: 13156 | Y42: 14549 | Z42: 15761 | AA42: 16901 | AB42: 17486 | AC42: 18277 | AD42: 19516 | AE42: 19821 | AF42: 19604 | AG42: 19188 | AH42: 20766 | AI42: =AI22 -> 20907 | AJ42: =AJ22 -> 21213 | AK42: =AK22 -> 22314 | AL42: =AL22 -> 23117
T43: Subscription Base | U43: 450 | V43: 480 | W43: 515 | X43: 550 | Y43: 585 | Z43: 620 | AA43: 660 | AB43: 700 | AC43: 745 | AD43: 785 | AE43: 825 | AF43: 860 | AG43: 900 | AH43: 935 | AI43: 975 | AJ43: =AI43+150 -> 1125
T44: (From Earnings Transcript) | AJ44: plus 150 than 2Q | AK44: more than 1b | AL44: more than 1b

Sheet Segment_A
A1: Sales | B1: FY2011 | C1: FY2012 | D1: FY2013 | E1: FY2014 | F1: FY2015 | G1: FY2016 | H1: FY2017 | I1: FY2018 | J1: FY2019 | K1: FY2020 | L1: FY2021 | M1: FY2022 | N1: FY2023 | O1: FY2024E | P1: FY2025E | Q1: FY2026E | R1: FY2027E | S1: FY2028E | T1: FY2029E
A2: iPhone | B2: 45998 | C2: 78692 | D2: 91279 | E2: 101991 | F2: 155041 | G2: 136700 | H2: 139337 | I2: 164888 | J2: 142381 | K2: 137781 | L2: 191973 | M2: 205489 | N2: 200583 | O2: =SUM(Segment_Q!AL2:AO2) -> 212428.56 | P2: =SUM(Segment_Q!AP2:AS2) -> 225237.22 | Q2: =P2*(1+Q11) -> 243256.2 | R2: =Q2*(1+R11) -> 262716.7 | S2: =R2*(1+S11) -> 283734.03 | T2: =S2*(1+T11) -> 306432.75
A3: Mac | B3: 21783 | C3: 23221 | D3: 21483 | E3: 24079 | F3: 25471 | G3: 22831 | H3: 25569 | I3: 25198 | J3: 25740 | K3: 28622 | L3: 35190 | M3: 40177 | N3: 29357 | O3: =SUM(Segment_Q!AL7:AO7) -> 30021.78 | P3: =SUM(Segment_Q!AP7:AS7) -> 32637.112 | Q3: =P3*(1+Q12) -> 33942.597 | R3: =Q3*(1+R12) -> 35300.301 | S3: =R3*(1+S12) -> 36712.313 | T3: =S3*(1+T12) -> 38180.805
A4: iPad | B4: 19168 | C4: 30945 | D4: 31980 | E4: 30283 | F4: 23227 | G4: 20628 | H4: 18802 | I4: 18380 | J4: 21280 | K4: 23724 | L4: 31862 | M4: 29292 | N4: 28300 | O4: =SUM(Segment_Q!AL12:AO12) -> 25404.559 | P4: =SUM(Segment_Q!AP12:AS12) -> 27553.821 | Q4: =P4*(1+Q13) -> 28655.974 | R4: =Q4*(1+R13) -> 29802.213 | S4: =R4*(1+S13) -> 30994.301 | T4: =S4*(1+T13) -> 32234.073
A5: Wearables, Home and Accessories | H5: 12826 | I5: 17381 | J5: 24482 | K5: 30620 | L5: 38367 | M5: 41241 | N5: 39845 | O5: =SUM(Segment_Q!AL17:AO17) -> 39676.263 | P5: =SUM(Segment_Q!AP17:AS17) -> 48035.271 | Q5: =P5*(1+Q14) -> 52838.799 | R5: =Q5*(1+R14) -> 58122.678 | S5: =R5*(1+S14) -> 63934.946 | T5: =S5*(1+T14) -> 70328.441
A6: Services | B6: 9373 | C6: 12890 | D6: 16051 | E6: 18063 | F6: 19909 | G6: 24348 | H6: 32700 | I6: 39748 | J6: 46291 | K6: 53768 | L6: 68425 | M6: 78129 | N6: 85200 | O6: =SUM(Segment_Q!AL22:AO22) -> 96763.331 | P6: =SUM(Segment_Q!AP22:AS22) -> 112322.31 | Q6: =P6*(1+Q15) -> 130293.88 | R6: =Q6*(1+R15) -> 151140.9 | S6: =R6*(1+S15) -> 175323.44 | T6: =S6*(1+T15) -> 203375.19
A7: Other Products | B7: =7453+4474 -> 11927 | C7: =5615+5145 -> 10760 | D7: 10117 | E7: 8379 | F7: 10067 | G7: 11132
A8: Total Net Sales | B8: =SUM(B2:B7) -> 108249 | C8: =SUM(C2:C7) -> 156508 | D8: =SUM(D2:D7) -> 170910 | E8: =SUM(E2:E7) -> 182795 | F8: =SUM(F2:F7) -> 233715 | G8: =SUM(G2:G7) -> 215639 | H8: =SUM(H2:H7) -> 229234 | I8: =SUM(I2:I7) -> 265595 | ... T8: =SUM(T2:T7) -> 650551.27
A10: YoY
A11: iPhone | C11: =C2/B2-1 -> 0.71077003 | D11: =D2/C2-1 -> 0.15995273 | E11: =E2/D2-1 -> 0.11735448 | F11: =F2/E2-1 -> 0.52014393 | G11: =G2/F2-1 -> -0.11829774 | H11: =H2/G2-1 -> 0.019290417 | I11: =I2/H2-1 -> 0.18337556 | J11: =J2/I2-1 -> -0.13649871 | ... P11: =P2/O2-1 -> 0.060296339 | Q11: =$Q22 -> 0.08 | R11: =$Q22 -> 0.08 | S11: =$Q22 -> 0.08 | T11: =$Q22 -> 0.08
A12: Mac | C12: =C3/B3-1 -> 0.066014782 | D12: =D3/C3-1 -> -0.074846045 | E12: =E3/D3-1 -> 0.12083973 | F12: =F3/E3-1 -> 0.05780971 | G12: =G3/F3-1 -> -0.10364729 | H12: =H3/G3-1 -> 0.11992466 | I12: =I3/H3-1 -> -0.014509758 | J12: =J3/I3-1 -> 0.021509644 | ... P12: =P3/O3-1 -> 0.087114484 | Q12: =$Q23 -> 0.04 | R12: =$Q23 -> 0.04 | S12: =$Q23 -> 0.04 | T12: =$Q23 -> 0.04
A13: iPad | C13: =C4/B4-1 -> 0.61440943 | D13: =D4/C4-1 -> 0.033446437 | E13: =E4/D4-1 -> -0.053064415 | F13: =F4/E4-1 -> -0.23300201 | G13: =G4/F4-1 -> -0.11189564 | H13: =H4/G4-1 -> -0.088520458 | I13: =I4/H4-1 -> -0.022444421 | J13: =J4/I4-1 -> 0.1577802 | ... P13: =P4/O4-1 -> 0.084601419 | Q13: =$Q24 -> 0.04 | R13: =$Q24 -> 0.04 | S13: =$Q24 -> 0.04 | T13: =$Q24 -> 0.04
A14: Wearables, Home and Accessories | C14: N/A | D14: N/A | E14: N/A | F14: N/A | G14: N/A | H14: N/A | I14: =I5/H5-1 -> 0.355138 | J14: =J5/I5-1 -> 0.40854957 | K14: =K5/J5-1 -> 0.25071481 | L14: =L5/K5-1 -> 0.25300457 | M14: =M5/L5-1 -> 0.074908124 | N14: =N5/M5-1 -> -0.03384981 | O14: =O5/N5-1 -> -0.0042348426 | P14: =P5/O5-1 -> 0.21068035 | Q14: =$Q25 -> 0.1 | R14: =$Q25 -> 0.1 | S14: =$Q25 -> 0.1 | T14: =$Q25 -> 0.1
A15: Services | C15: =C6/B6-1 -> 0.37522672 | D15: =D6/C6-1 -> 0.24522886 | E15: =E6/D6-1 -> 0.12535045 | F15: =F6/E6-1 -> 0.10219786 | G15: =G6/F6-1 -> 0.22296449 | H15: =H6/G6-1 -> 0.34302612 | I15: =I6/H6-1 -> 0.21553517 | J15: =J6/I6-1 -> 0.16461206 | ... P15: =P6/O6-1 -> 0.16079415 | Q15: =$Q26 -> 0.16 | R15: =$Q26 -> 0.16 | S15: =$Q26 -> 0.16 | T15: =$Q26 -> 0.16
A16: Other Products | C16: =C7/B7-1 -> -0.097845225 | D16: =D7/C7-1 -> -0.059758364 | E16: =E7/D7-1 -> -0.17179006 | F16: =F7/E7-1 -> 0.20145602 | G16: =G7/F7-1 -> 0.1057912 | H16: N/A | I16: N/A | J16: N/A | K16: N/A | L16: N/A | M16: N/A | N16: N/A | O16: N/A | P16: N/A | V16: Estimate LT Growth Rate
A17: Total Net Sales | C17: =C8/B8-1 -> 0.44581474 | D17: =D8/C8-1 -> 0.092020855 | E17: =E8/D8-1 -> 0.069539524 | F17: =F8/E8-1 -> 0.27856342 | G17: =G8/F8-1 -> -0.077342062 | H17: =H8/G8-1 -> 0.063045182 | I17: =I8/H8-1 -> 0.15861958 | J17: =J8/I8-1 -> -0.020410776 | ... T17: =T8/S8-1 -> 0.10132441 | V17: 0.05
O19: by Segment_Q | P19: by Segment_Q
P21: 5-yr avg | Q21: Our Estimate
O22: iPhone | P22: =AVERAGE(L11:P11) -> 0.11184056 | Q22: 0.08
O23: Mac | P23: =AVERAGE(L12:P12) -> 0.042328219 | Q23: 0.04
O24: iPad | P24: =AVERAGE(L13:P13) -> 0.042158187 | Q24: 0.04
O25: Wearables, Home and Accessories | P25: =AVERAGE(L14:P14) -> 0.10010168 | Q25: 0.1
O26: Services | P26: =AVERAGE(L15:P15) -> 0.16028695 | Q26: 0.16

Sheet DCF
B1: FY2023 | C1: FY2024E | D1: FY2025E | E1: FY2026E | F1: FY2027E | G1: FY2028E | H1: FY2029E | J1: Gross Margin Estimate | M1: Depreciation Expense Calculation | N1: FY2019 | O1: FY2020 | P1: FY2021 | Q1: FY2022 | R1: FY2023
A2: Product Revenue | C2: =SUM(Segment_A!O2:O5) -> 307531.16 | D2: =SUM(Segment_A!P2:P5) -> 333463.43 | E2: =SUM(Segment_A!Q2:Q5) -> 358693.57 | F2: =SUM(Segment_A!R2:R5) -> 385941.89 | G2: =SUM(Segment_A!S2:S5) -> 415375.59 | H2: =SUM(Segment_A!T2:T5) -> 447176.07 | J2: =IS!P33 -> 0.36 | M2: Revenue | N2: =IS!H23 -> 260174 | O2: =IS!I23 -> 274515 | P2: =IS!J23 -> 365817 | Q2: =IS!K23 -> 394328 | R2: =IS!L23 -> 383285
A3: Service Revenue | C3: =Segment_A!O6 -> 96763.331 | D3: =Segment_A!P6 -> 112322.31 | E3: =Segment_A!Q6 -> 130293.88 | F3: =Segment_A!R6 -> 151140.9 | G3: =Segment_A!S6 -> 175323.44 | H3: =Segment_A!T6 -> 203375.19 | J3: =IS!P34 -> 0.71 | M3: Dep & Amort from CFS | N3: =CF!H19 -> 12547 | O3: =CF!I19 -> 11056 | P3: =CF!J19 -> 11284 | Q3: =CF!K19 -> 11104 | R3: =CF!L19 -> 11519 | T3: 5-yr avg
A4: Total Revenue | C4: =SUM(C2:C3) -> 404294.49 | D4: =SUM(D2:D3) -> 445785.74 | E4: =SUM(E2:E3) -> 488987.45 | F4: =SUM(F2:F3) -> 537082.79 | G4: =SUM(G2:G3) -> 590699.03 | H4: =SUM(H2:H3) -> 650551.27 | M4: Dep / Revenue Ratio | N4: =N3/N2 -> 0.048225418 | O4: =O3/O2 -> 0.040274666 | P4: =P3/P2 -> 0.030846024 | Q4: =Q3/Q2 -> 0.028159299 | R4: =R3/R2 -> 0.030053355 | T4: =AVERAGE(N4:R4) -> 0.035511752
A5: Gross Profit | C5: =C2*$J$2+C3*$J$3 -> 179413.18 | D5: =D2*$J$2+D3*$J$3 -> 199795.67 | E5: =E2*$J$2+E3*$J$3 -> 221638.34 | F5: =F2*$J$2+F3*$J$3 -> 246249.12 | G5: =G2*$J$2+G3*$J$3 -> 274014.86 | H5: =H2*$J$2+H3*$J$3 -> 305379.77 | J5: Operating Exp/Revenue
A6: Operating Expense | C6: =C4*$J$6 -> 53899.951 | D6: =D4*$J$6 -> 59431.503 | E6: =E4*$J$6 -> 65191.092 | F6: =F4*$J$6 -> 71603.093 | G6: =G4*$J$6 -> 78751.133 | H6: =H4*$J$6 -> 86730.545 | J6: =IS!P53 -> 0.13331854 | M6: Capex Calculation | N6: FY2019 | O6: FY2020 | P6: FY2021 | Q6: FY2022 | R6: FY2023
A7: Operating Profit | C7: =C5-C6 -> 125513.23 | D7: =D5-D6 -> 140364.17 | E7: =E5-E6 -> 156447.25 | F7: =F5-F6 -> 174646.02 | G7: =G5-G6 -> 195263.72 | H7: =H5-H6 -> 218649.23 | M7: Revenue | N7: =IS!H23 -> 260174 | O7: =IS!I23 -> 274515 | P7: =IS!J23 -> 365817 | Q7: =IS!K23 -> 394328 | R7: =IS!L23 -> 383285
A8: Dep & Amort Expense | C8: =C4*$T$4 -> 14357.206 | D8: =D4*$T$4 -> 15830.633 | E8: =E4*$T$4 -> 17364.801 | F8: =F4*$T$4 -> 19072.751 | G8: =G4*$T$4 -> 20976.758 | H8: =H4*$T$4 -> 23102.216 | M8: Capex from CFS | N8: =CF!H48 -> -10495 | O8: =CF!I48 -> -7309 | P8: =CF!J48 -> -11085 | Q8: =CF!K48 -> -10708 | R8: =CF!L48 -> -10959 | T8: 5-yr avg
A9: Taxable Income | C9: =C7-C8 -> 111156.03 | D9: =D7-D8 -> 124533.54 | E9: =E7-E8 -> 139082.44 | F9: =F7-F8 -> 155573.27 | G9: =G7-G8 -> 174286.97 | H9: =H7-H8 -> 195547.01 | J9: Tax Rate | M9: Capex / Revenue Ratio | N9: =-N8/N7 -> 0.040338389 | O9: =-O8/O7 -> 0.026625139 | P9: =-P8/P7 -> 0.030302036 | Q9: =-Q8/Q7 -> 0.027155059 | R9: =-R8/R7 -> 0.028592301 | T9: =AVERAGE(N9:R9) -> 0.030602585
A10: Tax Expense | C10: =C9*$J$10 -> 16584.012 | D10: =D9*$J$10 -> 18579.88 | E10: =E9*$J$10 -> 20750.516 | F10: =F9*$J$10 -> 23210.879 | G10: =G9*$J$10 -> 26002.883 | H10: =H9*$J$10 -> 29174.792 | J10: =IS!O84 -> 0.1491958
M11: Net Working Capital Calculation | N11: FY2019 | O11: FY2020 | P11: FY2021 | Q11: FY2022 | R11: FY2023
